#VRML_SIM R2023a utf8

EXTERNPROTO "https://raw.githubusercontent.com/cyberbotics/webots/R2023a/projects/objects/trees/protos/BigSassafras.proto"
EXTERNPROTO "https://raw.githubusercontent.com/cyberbotics/webots/R2023a/projects/objects/trees/protos/Cypress.proto"
EXTERNPROTO "https://raw.githubusercontent.com/cyberbotics/webots/R2023a/projects/appearances/protos/DryMud.proto"
EXTERNPROTO "https://raw.githubusercontent.com/cyberbotics/webots/R2023a/projects/objects/trees/protos/Oak.proto"
EXTERNPROTO "https://raw.githubusercontent.com/cyberbotics/webots/R2023a/projects/appearances/protos/PaintedWood.proto"
EXTERNPROTO "https://raw.githubusercontent.com/cyberbotics/webots/R2023a/projects/objects/trees/protos/Pine.proto"
EXTERNPROTO "https://raw.githubusercontent.com/cyberbotics/webots/R2023a/projects/appearances/protos/Rubber.proto"
EXTERNPROTO "https://raw.githubusercontent.com/cyberbotics/webots/R2023a/projects/objects/trees/protos/SimpleTree.proto"
EXTERNPROTO "https://raw.githubusercontent.com/cyberbotics/webots/R2023a/projects/objects/backgrounds/protos/TexturedBackground.proto"
EXTERNPROTO "https://raw.githubusercontent.com/cyberbotics/webots/R2023a/projects/objects/backgrounds/protos/TexturedBackgroundLight.proto"
EXTERNPROTO "https://raw.githubusercontent.com/cyberbotics/webots/R2023a/projects/objects/floors/protos/UnevenTerrain.proto"

WorldInfo {
}
Viewpoint {
  orientation -0.1094860278094318 -0.03539947914157163 0.9933577837773345 3.763158221708053
  position 22.473367067916993 7.435111639958959 13.517257614276327
}
TexturedBackground {
}
TexturedBackgroundLight {
}
Robot {
  translation 3.1184447284928365 -3.1422033278707064 4.034126043121298
  rotation 0.08699285409561112 0.011415134200423569 -0.9961435328543201 1.4783388896493246
  children [
    DEF base Shape {
      appearance PaintedWood {
        colorOverride 0 0.2 0.1
      }
      geometry DEF Base Box {
        size 1.2 3 1
      }
    }
    DEF wheel1 HingeJoint {
      jointParameters HingeJointParameters {
        position -20.727783478344378
        anchor 0.75 -0.96 -0.53
      }
      device [
        RotationalMotor {
          name "wheel1"
          maxTorque 40
        }
      ]
      endPoint Solid {
        translation 0.75 -0.96 -0.53
        rotation 0.6280237449509553 -0.4595265923935018 0.6280298453584781 4.003082760783794
        children [
          DEF wheel Shape {
            appearance Rubber {
            }
            geometry Cylinder {
              height 0.5
              radius 0.5
            }
          }
        ]
        boundingObject USE wheel
        physics DEF phy1 Physics {
          mass 1
        }
        linearVelocity -1.2655242070523816e-05 -1.2258907577694005e-05 -2.149204982913478e-06
        angularVelocity 1.6169049316364603e-07 -2.3609816462469244e-09 -8.216416665842515e-08
      }
    }
    DEF wheel2 HingeJoint {
      jointParameters HingeJointParameters {
        position -45.164346450319755
        anchor -0.75 -0.96 -0.53
      }
      device [
        RotationalMotor {
          name "wheel2"
          maxTorque 40
        }
      ]
      endPoint Solid {
        translation -0.75 -0.96 -0.53
        rotation 0.4867442574685712 -0.7253654890612805 0.4867493555211539 4.396680191133992
        children [
          DEF wheel Shape {
            appearance Rubber {
            }
            geometry Cylinder {
              height 0.5
              radius 0.5
            }
          }
        ]
        name "solid(1)"
        boundingObject USE wheel
        physics USE phy1
        linearVelocity -1.2533397498017957e-05 -1.2268467170549975e-05 -1.909669040401247e-06
        angularVelocity 1.0685126604173903e-06 -9.060116100750053e-06 -9.049172521862578e-07
      }
    }
    DEF wheel3 HingeJoint {
      jointParameters HingeJointParameters {
        position -30.518689618395157
        anchor 0.75 0.96 -0.53
      }
      device [
        RotationalMotor {
          name "wheel3"
          maxTorque 40
        }
      ]
      endPoint Solid {
        translation 0.75 0.96 -0.53
        rotation -0.39790488086619186 -0.8266445590912364 -0.39790762584765454 4.523138950326833
        children [
          DEF wheel Shape {
            appearance Rubber {
            }
            geometry Cylinder {
              height 0.5
              radius 0.5
            }
          }
        ]
        name "solid(2)"
        boundingObject USE wheel
        physics USE phy1
        linearVelocity -1.2640990604111818e-05 -1.2439190095815173e-05 -2.1162139373700477e-06
        angularVelocity 1.0774614136139074e-06 -9.151407202558057e-06 -9.133135328204834e-07
      }
    }
    DEF wheel4 HingeJoint {
      jointParameters HingeJointParameters {
        position -49.85886537545353
        anchor -0.75 0.96 -0.53
      }
      device [
        RotationalMotor {
          name "wheel4"
          maxTorque 40
        }
      ]
      endPoint Solid {
        translation -0.75 0.96 -0.53
        rotation 0.1979163516763759 0.9600301624122582 0.19791716701136916 1.6115847749557541
        children [
          DEF wheel Shape {
            appearance Rubber {
            }
            geometry Cylinder {
              height 0.5
              radius 0.5
            }
          }
        ]
        name "solid(3)"
        boundingObject USE wheel
        physics USE phy1
        linearVelocity -1.2519170258225927e-05 -1.2448791294065813e-05 -1.8762875217817043e-06
        angularVelocity 1.6164183634757883e-07 -2.3585967094519314e-09 -8.216699218320484e-08
      }
    }
  ]
  boundingObject USE base
  physics USE phy1
  controller "forest_controller"
  linearVelocity -1.259266313732832e-05 -1.2435980210831587e-05 -2.021233072071027e-06
  angularVelocity 1.6164183486505838e-07 -2.3585969275361626e-09 -8.216699262244438e-08
}
DEF forest Solid {
  children [
    Pine {
      translation -15.62 20.85 1.15
      name "pine tree(6)"
    }
    Pine {
      translation -15.62 -10.45 1.15
      name "pine tree(5)"
    }
    Pine {
      translation 11.67 -10.45 1.45
      name "pine tree(3)"
    }
    Pine {
      translation 20.49 -10.45 2.81
      name "pine tree(4)"
    }
    Pine {
      translation 11.67 15.84 1.88
      name "pine tree(2)"
    }
    Pine {
      translation -4.35 9.25 2.22
      name "pine tree(1)"
    }
    Pine {
      translation -4.35 -3.53 2.18
    }
    SimpleTree {
      translation 0 0 3
    }
    SimpleTree {
      translation 6 0 3
      name "tree(1)"
    }
    SimpleTree {
      translation 6 10 3
      name "tree(2)"
    }
    SimpleTree {
      translation 16 15 3
      name "tree(3)"
    }
    SimpleTree {
      translation -16 -15 1.8
      name "tree(4)"
    }
    SimpleTree {
      translation 16 -15 3
      name "tree(5)"
    }
    SimpleTree {
      translation 5 -22 2
      name "tree(6)"
    }
    SimpleTree {
      translation -15 -22 2
      name "tree(7)"
    }
    SimpleTree {
      translation -9 22 2
      name "tree(8)"
    }
    SimpleTree {
      translation -18 16 2.5
      name "tree(9)"
    }
    SimpleTree {
      translation -22 -3 2
      name "tree(10)"
    }
    SimpleTree {
      translation 10 -8 3
      name "tree(11)"
    }
    SimpleTree {
      translation -5 -8 2.3
      name "tree(12)"
    }
    SimpleTree {
      translation 1 -17 2
      name "tree(13)"
    }
    Oak {
      translation 14.94 0 3.24
    }
    Oak {
      translation 20 -5.97 3.28
      name "oak tree(1)"
    }
    Oak {
      translation 15.97 -10.75 3.02
      name "oak tree(2)"
    }
    Oak {
      translation 15.97 11.04 3.07
      name "oak tree(3)"
    }
    Oak {
      translation -24.52 6.27 2.46
      name "oak tree(4)"
    }
    Oak {
      translation -12.06 2.39 2.09
      name "oak tree(6)"
    }
    Oak {
      translation -13.84 10.96 2.09
      name "oak tree(7)"
    }
    Oak {
      translation -2.97 18.97 1.79
      name "oak tree(8)"
    }
    Oak {
      translation 0.35 13.07 2.24
      name "oak tree(9)"
    }
    Oak {
      translation -9.22 15.64 2.72
      name "oak tree(5)"
    }
    Oak {
      translation 7.46 20.45 2.43
      name "oak tree(10)"
    }
    Oak {
      translation 16.74 21.4 2.43
      name "oak tree(11)"
    }
    BigSassafras {
      translation -11.82 -13.71 1.72
    }
    BigSassafras {
      translation -21.32 -8.95 1.72
      name "sassafras tree(1)"
    }
    BigSassafras {
      translation 19.67 7.95 3.44
      name "sassafras tree(2)"
    }
    BigSassafras {
      translation 19.67 -1.13 2.97
      name "sassafras tree(3)"
    }
    BigSassafras {
      translation 21.66 -19.93 2.97
      name "sassafras tree(4)"
    }
    BigSassafras {
      translation 9.84 -19.93 2.64
      name "sassafras tree(5)"
    }
    BigSassafras {
      translation -6.69 -19.93 1.29
      name "sassafras tree(6)"
    }
    BigSassafras {
      translation -16.82 -5.16 2.98
      name "sassafras tree(7)"
    }
    BigSassafras {
      translation -16.82 8.12 2.98
      name "sassafras tree(8)"
    }
    BigSassafras {
      translation -21.82 21.14 2.98
      name "sassafras tree(9)"
    }
    BigSassafras {
      translation 1.95 21.14 2.63
      name "sassafras tree(10)"
    }
    Cypress {
      translation -11.36 0 1.96
    }
    Cypress {
      translation -14.16 5.78 2.06
      name "cypress tree(1)"
    }
    Cypress {
      translation 20.42 15.8 3.01
      name "cypress tree(2)"
    }
    Cypress {
      translation 21.87 20.79 3.01
      name "cypress tree(3)"
    }
    Cypress {
      translation 11.51 1.81 3.01
      name "cypress tree(4)"
    }
    Cypress {
      translation 2.77 -10.75 2.51
      name "cypress tree(5)"
    }
    Cypress {
      translation -2.24 -21.57 1.87
      name "cypress tree(6)"
    }
    Cypress {
      translation 15.22 -21.57 2.5
      name "cypress tree(7)"
    }
    Cypress {
      translation 6.61 -15.53 2.8
      name "cypress tree(8)"
    }
    Cypress {
      translation -11.26 5.51 2.26
      name "cypress tree(9)"
    }
  ]
}
UnevenTerrain {
}
DEF Border Solid {
  translation 0 0 3.9
  children [
    Solid {
      translation 0 -25.2 -0.37003136092665656
      children [
        DEF border Shape {
          appearance DryMud {
          }
          geometry Box {
            size 49 1 3
          }
        }
      ]
      name "border1"
      boundingObject USE border
      physics DEF phy1 Physics {
        mass 1
      }
      linearVelocity 0 0 -1.2139209860606136e-07
    }
    Solid {
      translation 0 25.53 -0.37003136092665656
      children [
        DEF border Shape {
          appearance DryMud {
          }
          geometry Box {
            size 49 1 3
          }
        }
      ]
      name "border2"
      boundingObject USE border
      physics USE phy1
      linearVelocity 0 0 -1.2139209860606136e-07
    }
    Solid {
      translation 25.53 0 -0.37
      rotation 0 0 1 1.5708
      children [
        DEF border Shape {
          appearance DryMud {
          }
          geometry Box {
            size 49 1 3
          }
        }
      ]
      name "border3"
      boundingObject USE border
    }
    Solid {
      translation -25.5301 1.57462e-05 -0.37003136092665656
      rotation 5.1580022398749126e-05 -9.550089548459884e-05 0.9999999941095401 1.569814080916819
      children [
        DEF border Shape {
          appearance DryMud {
          }
          geometry Box {
            size 49 1 3
          }
        }
      ]
      name "border4"
      boundingObject USE border
      physics USE phy1
      linearVelocity 0 0 -1.2139209860606136e-07
    }
  ]
  name "solid(1)"
}
